Traceback (most recent call last):
  File "C:\Users\lihkir\Anaconda3\envs\ml_tf\lib\site-packages\jupyter_cache\executors\utils.py", line 58, in single_nb_execution
    executenb(
  File "C:\Users\lihkir\Anaconda3\envs\ml_tf\lib\site-packages\nbclient\client.py", line 1305, in execute
    return NotebookClient(nb=nb, resources=resources, km=km, **kwargs).execute()
  File "C:\Users\lihkir\Anaconda3\envs\ml_tf\lib\site-packages\jupyter_core\utils\__init__.py", line 98, in wrapped
    return loop.run_until_complete(inner)
  File "C:\Users\lihkir\Anaconda3\envs\ml_tf\lib\asyncio\base_events.py", line 647, in run_until_complete
    return future.result()
  File "C:\Users\lihkir\Anaconda3\envs\ml_tf\lib\site-packages\nbclient\client.py", line 705, in async_execute
    await self.async_execute_cell(
  File "C:\Users\lihkir\Anaconda3\envs\ml_tf\lib\site-packages\nbclient\client.py", line 1058, in async_execute_cell
    await self._check_raise_for_error(cell, cell_index, exec_reply)
  File "C:\Users\lihkir\Anaconda3\envs\ml_tf\lib\site-packages\nbclient\client.py", line 914, in _check_raise_for_error
    raise CellExecutionError.from_cell_and_msg(cell, exec_reply_content)
nbclient.exceptions.CellExecutionError: An error occurred while executing the following cell:
------------------
best_model = load_model(os.path.join('keras_models', 'PRSA_data_Air_Pressure_MLP_weights.05-0.0001.keras'), compile=False)
preds = best_model.predict(X_val)
pred_PRES = scaler.inverse_transform(preds)
pred_PRES = np.squeeze(pred_PRES)
------------------


[1;31m---------------------------------------------------------------------------[0m
[1;31mOSError[0m                                   Traceback (most recent call last)
Cell [1;32mIn[29], line 1[0m
[1;32m----> 1[0m best_model [38;5;241m=[39m [43mload_model[49m[43m([49m[43mos[49m[38;5;241;43m.[39;49m[43mpath[49m[38;5;241;43m.[39;49m[43mjoin[49m[43m([49m[38;5;124;43m'[39;49m[38;5;124;43mkeras_models[39;49m[38;5;124;43m'[39;49m[43m,[49m[43m [49m[38;5;124;43m'[39;49m[38;5;124;43mPRSA_data_Air_Pressure_MLP_weights.05-0.0001.keras[39;49m[38;5;124;43m'[39;49m[43m)[49m[43m,[49m[43m [49m[38;5;28;43mcompile[39;49m[38;5;241;43m=[39;49m[38;5;28;43;01mFalse[39;49;00m[43m)[49m
[0;32m      2[0m preds [38;5;241m=[39m best_model[38;5;241m.[39mpredict(X_val)
[0;32m      3[0m pred_PRES [38;5;241m=[39m scaler[38;5;241m.[39minverse_transform(preds)

File [1;32m~\Anaconda3\envs\ml_tf\lib\site-packages\keras\utils\traceback_utils.py:70[0m, in [0;36mfilter_traceback.<locals>.error_handler[1;34m(*args, **kwargs)[0m
[0;32m     67[0m     filtered_tb [38;5;241m=[39m _process_traceback_frames(e[38;5;241m.[39m__traceback__)
[0;32m     68[0m     [38;5;66;03m# To get the full stack trace, call:[39;00m
[0;32m     69[0m     [38;5;66;03m# `tf.debugging.disable_traceback_filtering()`[39;00m
[1;32m---> 70[0m     [38;5;28;01mraise[39;00m e[38;5;241m.[39mwith_traceback(filtered_tb) [38;5;28;01mfrom[39;00m [38;5;28;01mNone[39;00m
[0;32m     71[0m [38;5;28;01mfinally[39;00m:
[0;32m     72[0m     [38;5;28;01mdel[39;00m filtered_tb

File [1;32m~\Anaconda3\envs\ml_tf\lib\site-packages\h5py\_hl\files.py:567[0m, in [0;36mFile.__init__[1;34m(self, name, mode, driver, libver, userblock_size, swmr, rdcc_nslots, rdcc_nbytes, rdcc_w0, track_order, fs_strategy, fs_persist, fs_threshold, fs_page_size, page_buf_size, min_meta_keep, min_raw_keep, locking, alignment_threshold, alignment_interval, meta_block_size, **kwds)[0m
[0;32m    558[0m     fapl [38;5;241m=[39m make_fapl(driver, libver, rdcc_nslots, rdcc_nbytes, rdcc_w0,
[0;32m    559[0m                      locking, page_buf_size, min_meta_keep, min_raw_keep,
[0;32m    560[0m                      alignment_threshold[38;5;241m=[39malignment_threshold,
[0;32m    561[0m                      alignment_interval[38;5;241m=[39malignment_interval,
[0;32m    562[0m                      meta_block_size[38;5;241m=[39mmeta_block_size,
[0;32m    563[0m                      [38;5;241m*[39m[38;5;241m*[39mkwds)
[0;32m    564[0m     fcpl [38;5;241m=[39m make_fcpl(track_order[38;5;241m=[39mtrack_order, fs_strategy[38;5;241m=[39mfs_strategy,
[0;32m    565[0m                      fs_persist[38;5;241m=[39mfs_persist, fs_threshold[38;5;241m=[39mfs_threshold,
[0;32m    566[0m                      fs_page_size[38;5;241m=[39mfs_page_size)
[1;32m--> 567[0m     fid [38;5;241m=[39m make_fid(name, mode, userblock_size, fapl, fcpl, swmr[38;5;241m=[39mswmr)
[0;32m    569[0m [38;5;28;01mif[39;00m [38;5;28misinstance[39m(libver, [38;5;28mtuple[39m):
[0;32m    570[0m     [38;5;28mself[39m[38;5;241m.[39m_libver [38;5;241m=[39m libver

File [1;32m~\Anaconda3\envs\ml_tf\lib\site-packages\h5py\_hl\files.py:231[0m, in [0;36mmake_fid[1;34m(name, mode, userblock_size, fapl, fcpl, swmr)[0m
[0;32m    229[0m     [38;5;28;01mif[39;00m swmr [38;5;129;01mand[39;00m swmr_support:
[0;32m    230[0m         flags [38;5;241m|[39m[38;5;241m=[39m h5f[38;5;241m.[39mACC_SWMR_READ
[1;32m--> 231[0m     fid [38;5;241m=[39m [43mh5f[49m[38;5;241;43m.[39;49m[43mopen[49m[43m([49m[43mname[49m[43m,[49m[43m [49m[43mflags[49m[43m,[49m[43m [49m[43mfapl[49m[38;5;241;43m=[39;49m[43mfapl[49m[43m)[49m
[0;32m    232[0m [38;5;28;01melif[39;00m mode [38;5;241m==[39m [38;5;124m'[39m[38;5;124mr+[39m[38;5;124m'[39m:
[0;32m    233[0m     fid [38;5;241m=[39m h5f[38;5;241m.[39mopen(name, h5f[38;5;241m.[39mACC_RDWR, fapl[38;5;241m=[39mfapl)

File [1;32mh5py\_objects.pyx:54[0m, in [0;36mh5py._objects.with_phil.wrapper[1;34m()[0m

File [1;32mh5py\_objects.pyx:55[0m, in [0;36mh5py._objects.with_phil.wrapper[1;34m()[0m

File [1;32mh5py\h5f.pyx:106[0m, in [0;36mh5py.h5f.open[1;34m()[0m

[1;31mOSError[0m: Unable to open file (file signature not found)

